2018-10-19 15:01:26,260 ERROR: Exception on /login [GET] [in c:\users\administrator.pb1501034\microblog\venv\lib\site-packages\flask\app.py:1761]
Traceback (most recent call last):
  File "c:\users\administrator.pb1501034\microblog\venv\lib\site-packages\flask\app.py", line 2292, in wsgi_app
    response = self.full_dispatch_request()
  File "c:\users\administrator.pb1501034\microblog\venv\lib\site-packages\flask\app.py", line 1815, in full_dispatch_request
    rv = self.handle_user_exception(e)
  File "c:\users\administrator.pb1501034\microblog\venv\lib\site-packages\flask\app.py", line 1718, in handle_user_exception
    reraise(exc_type, exc_value, tb)
  File "c:\users\administrator.pb1501034\microblog\venv\lib\site-packages\flask\_compat.py", line 35, in reraise
    raise value
  File "c:\users\administrator.pb1501034\microblog\venv\lib\site-packages\flask\app.py", line 1813, in full_dispatch_request
    rv = self.dispatch_request()
  File "c:\users\administrator.pb1501034\microblog\venv\lib\site-packages\flask\app.py", line 1799, in dispatch_request
    return self.view_functions[rule.endpoint](**req.view_args)
  File "C:\Users\Administrator.PB1501034\microblog\app\routes.py", line 48, in login
    return render_template('login.html', title='Sign In', form=form)
  File "c:\users\administrator.pb1501034\microblog\venv\lib\site-packages\flask\templating.py", line 135, in render_template
    context, ctx.app)
  File "c:\users\administrator.pb1501034\microblog\venv\lib\site-packages\flask\templating.py", line 117, in _render
    rv = template.render(context)
  File "c:\users\administrator.pb1501034\microblog\venv\lib\site-packages\jinja2\asyncsupport.py", line 76, in render
    return original_render(self, *args, **kwargs)
  File "c:\users\administrator.pb1501034\microblog\venv\lib\site-packages\jinja2\environment.py", line 1008, in render
    return self.environment.handle_exception(exc_info, True)
  File "c:\users\administrator.pb1501034\microblog\venv\lib\site-packages\jinja2\environment.py", line 780, in handle_exception
    reraise(exc_type, exc_value, tb)
  File "c:\users\administrator.pb1501034\microblog\venv\lib\site-packages\jinja2\_compat.py", line 37, in reraise
    raise value.with_traceback(tb)
  File "C:\Users\Administrator.PB1501034\microblog\app\templates\login.html", line 1, in top-level template code
    {% extends "base.html" %}
  File "C:\Users\Administrator.PB1501034\microblog\app\templates\base.html", line 31, in top-level template code
    {% block content %}{% endblock %}
  File "C:\Users\Administrator.PB1501034\microblog\app\templates\login.html", line 26, in block "content"
    <a href="{{ url_for('reset_password_request') }}">Click to Reset It</a>
  File "c:\users\administrator.pb1501034\microblog\venv\lib\site-packages\flask\helpers.py", line 356, in url_for
    return appctx.app.handle_url_build_error(error, endpoint, values)
  File "c:\users\administrator.pb1501034\microblog\venv\lib\site-packages\flask\app.py", line 2061, in handle_url_build_error
    reraise(exc_type, exc_value, tb)
  File "c:\users\administrator.pb1501034\microblog\venv\lib\site-packages\flask\_compat.py", line 35, in reraise
    raise value
  File "c:\users\administrator.pb1501034\microblog\venv\lib\site-packages\flask\helpers.py", line 345, in url_for
    force_external=external)
  File "c:\users\administrator.pb1501034\microblog\venv\lib\site-packages\werkzeug\routing.py", line 1776, in build
    raise BuildError(endpoint, values, method, self)
werkzeug.routing.BuildError: Could not build url for endpoint 'reset_password_request'. Did you mean 'edit_profile' instead?
2018-10-19 15:05:54,808 INFO: Microblog startup [in C:\Users\Administrator.PB1501034\microblog\app\__init__.py:32]
2018-10-19 15:30:02,110 INFO: Microblog startup [in C:\Users\Administrator.PB1501034\microblog\app\__init__.py:32]
2018-10-19 15:30:17,862 ERROR: Exception on /reset_password_request [POST] [in c:\users\administrator.pb1501034\microblog\venv\lib\site-packages\flask\app.py:1761]
Traceback (most recent call last):
  File "c:\users\administrator.pb1501034\microblog\venv\lib\site-packages\flask\app.py", line 2292, in wsgi_app
    response = self.full_dispatch_request()
  File "c:\users\administrator.pb1501034\microblog\venv\lib\site-packages\flask\app.py", line 1815, in full_dispatch_request
    rv = self.handle_user_exception(e)
  File "c:\users\administrator.pb1501034\microblog\venv\lib\site-packages\flask\app.py", line 1718, in handle_user_exception
    reraise(exc_type, exc_value, tb)
  File "c:\users\administrator.pb1501034\microblog\venv\lib\site-packages\flask\_compat.py", line 35, in reraise
    raise value
  File "c:\users\administrator.pb1501034\microblog\venv\lib\site-packages\flask\app.py", line 1813, in full_dispatch_request
    rv = self.dispatch_request()
  File "c:\users\administrator.pb1501034\microblog\venv\lib\site-packages\flask\app.py", line 1799, in dispatch_request
    return self.view_functions[rule.endpoint](**req.view_args)
  File "C:\Users\Administrator.PB1501034\microblog\app\routes.py", line 166, in reset_password_request
    send_password_reset_email(user)
NameError: name 'send_password_reset_email' is not defined
2018-10-19 15:31:09,985 INFO: Microblog startup [in C:\Users\Administrator.PB1501034\microblog\app\__init__.py:32]
